2023-10-29 16:28:26,096 - ERROR - [Errno 11001] getaddrinfo failed
Traceback (most recent call last):
  File "C:\Users\cs439\PycharmProjects\pythonProject4\main.py", line 89, in translate_docx
    translated_chunk = translator.translate(chunk, src=src_lang, dest=dest_lang).text
                       ^^^^^^^^^^^^^^^^^^^^^^^^^^^^^^^^^^^^^^^^^^^^^^^^^^^^^^^^^
  File "C:\Program Files\Python312\Lib\site-packages\googletrans\client.py", line 194, in translate
    data, response = self._translate(text, dest, src)
                     ^^^^^^^^^^^^^^^^^^^^^^^^^^^^^^^^
  File "C:\Program Files\Python312\Lib\site-packages\googletrans\client.py", line 120, in _translate
    r = self.client.post(url, params=params, data=data)
        ^^^^^^^^^^^^^^^^^^^^^^^^^^^^^^^^^^^^^^^^^^^^^^^
  File "C:\Program Files\Python312\Lib\site-packages\httpx\_client.py", line 824, in post
    return self.request(
           ^^^^^^^^^^^^^
  File "C:\Program Files\Python312\Lib\site-packages\httpx\_client.py", line 600, in request
    return self.send(
           ^^^^^^^^^^
  File "C:\Program Files\Python312\Lib\site-packages\httpx\_client.py", line 620, in send
    response = self.send_handling_redirects(
               ^^^^^^^^^^^^^^^^^^^^^^^^^^^^^
  File "C:\Program Files\Python312\Lib\site-packages\httpx\_client.py", line 647, in send_handling_redirects
    response = self.send_handling_auth(
               ^^^^^^^^^^^^^^^^^^^^^^^^
  File "C:\Program Files\Python312\Lib\site-packages\httpx\_client.py", line 684, in send_handling_auth
    response = self.send_single_request(request, timeout)
               ^^^^^^^^^^^^^^^^^^^^^^^^^^^^^^^^^^^^^^^^^^
  File "C:\Program Files\Python312\Lib\site-packages\httpx\_client.py", line 714, in send_single_request
    ) = transport.request(
        ^^^^^^^^^^^^^^^^^^
  File "C:\Program Files\Python312\Lib\site-packages\httpcore\_sync\connection_pool.py", line 152, in request
    response = connection.request(
               ^^^^^^^^^^^^^^^^^^^
  File "C:\Program Files\Python312\Lib\site-packages\httpcore\_sync\connection.py", line 65, in request
    self.socket = self._open_socket(timeout)
                  ^^^^^^^^^^^^^^^^^^^^^^^^^^
  File "C:\Program Files\Python312\Lib\site-packages\httpcore\_sync\connection.py", line 85, in _open_socket
    return self.backend.open_tcp_stream(
           ^^^^^^^^^^^^^^^^^^^^^^^^^^^^^
  File "C:\Program Files\Python312\Lib\site-packages\httpcore\_backends\sync.py", line 133, in open_tcp_stream
    with map_exceptions(exc_map):
  File "C:\Users\cs439\AppData\Local\Programs\Python\Python312\Lib\contextlib.py", line 155, in __exit__
    self.gen.throw(value)
  File "C:\Program Files\Python312\Lib\site-packages\httpcore\_exceptions.py", line 12, in map_exceptions
    raise to_exc(exc) from None
httpcore._exceptions.ConnectError: [Errno 11001] getaddrinfo failed
2023-10-29 16:28:26,096 - INFO - Translated 30 characters, 5 words, and 1 sentences from Turkish to Zulu.
2023-10-29 16:28:54,005 - ERROR - [Errno 11001] getaddrinfo failed
Traceback (most recent call last):
  File "C:\Users\cs439\PycharmProjects\pythonProject4\main.py", line 89, in translate_docx
    translated_chunk = translator.translate(chunk, src=src_lang, dest=dest_lang).text
                       ^^^^^^^^^^^^^^^^^^^^^^^^^^^^^^^^^^^^^^^^^^^^^^^^^^^^^^^^^
  File "C:\Program Files\Python312\Lib\site-packages\googletrans\client.py", line 194, in translate
    data, response = self._translate(text, dest, src)
                     ^^^^^^^^^^^^^^^^^^^^^^^^^^^^^^^^
  File "C:\Program Files\Python312\Lib\site-packages\googletrans\client.py", line 120, in _translate
    r = self.client.post(url, params=params, data=data)
        ^^^^^^^^^^^^^^^^^^^^^^^^^^^^^^^^^^^^^^^^^^^^^^^
  File "C:\Program Files\Python312\Lib\site-packages\httpx\_client.py", line 824, in post
    return self.request(
           ^^^^^^^^^^^^^
  File "C:\Program Files\Python312\Lib\site-packages\httpx\_client.py", line 600, in request
    return self.send(
           ^^^^^^^^^^
  File "C:\Program Files\Python312\Lib\site-packages\httpx\_client.py", line 620, in send
    response = self.send_handling_redirects(
               ^^^^^^^^^^^^^^^^^^^^^^^^^^^^^
  File "C:\Program Files\Python312\Lib\site-packages\httpx\_client.py", line 647, in send_handling_redirects
    response = self.send_handling_auth(
               ^^^^^^^^^^^^^^^^^^^^^^^^
  File "C:\Program Files\Python312\Lib\site-packages\httpx\_client.py", line 684, in send_handling_auth
    response = self.send_single_request(request, timeout)
               ^^^^^^^^^^^^^^^^^^^^^^^^^^^^^^^^^^^^^^^^^^
  File "C:\Program Files\Python312\Lib\site-packages\httpx\_client.py", line 714, in send_single_request
    ) = transport.request(
        ^^^^^^^^^^^^^^^^^^
  File "C:\Program Files\Python312\Lib\site-packages\httpcore\_sync\connection_pool.py", line 152, in request
    response = connection.request(
               ^^^^^^^^^^^^^^^^^^^
  File "C:\Program Files\Python312\Lib\site-packages\httpcore\_sync\connection.py", line 65, in request
    self.socket = self._open_socket(timeout)
                  ^^^^^^^^^^^^^^^^^^^^^^^^^^
  File "C:\Program Files\Python312\Lib\site-packages\httpcore\_sync\connection.py", line 85, in _open_socket
    return self.backend.open_tcp_stream(
           ^^^^^^^^^^^^^^^^^^^^^^^^^^^^^
  File "C:\Program Files\Python312\Lib\site-packages\httpcore\_backends\sync.py", line 133, in open_tcp_stream
    with map_exceptions(exc_map):
  File "C:\Users\cs439\AppData\Local\Programs\Python\Python312\Lib\contextlib.py", line 155, in __exit__
    self.gen.throw(value)
  File "C:\Program Files\Python312\Lib\site-packages\httpcore\_exceptions.py", line 12, in map_exceptions
    raise to_exc(exc) from None
httpcore._exceptions.ConnectError: [Errno 11001] getaddrinfo failed
2023-10-29 16:28:54,005 - INFO - Translated 30 characters, 5 words, and 1 sentences from Turkish to Uyghur.
2023-10-29 16:29:46,909 - ERROR - [Errno 11001] getaddrinfo failed
Traceback (most recent call last):
  File "C:\Users\cs439\PycharmProjects\pythonProject4\main.py", line 89, in translate_docx
    translated_chunk = translator.translate(chunk, src=src_lang, dest=dest_lang).text
                       ^^^^^^^^^^^^^^^^^^^^^^^^^^^^^^^^^^^^^^^^^^^^^^^^^^^^^^^^^
  File "C:\Program Files\Python312\Lib\site-packages\googletrans\client.py", line 194, in translate
    data, response = self._translate(text, dest, src)
                     ^^^^^^^^^^^^^^^^^^^^^^^^^^^^^^^^
  File "C:\Program Files\Python312\Lib\site-packages\googletrans\client.py", line 120, in _translate
    r = self.client.post(url, params=params, data=data)
        ^^^^^^^^^^^^^^^^^^^^^^^^^^^^^^^^^^^^^^^^^^^^^^^
  File "C:\Program Files\Python312\Lib\site-packages\httpx\_client.py", line 824, in post
    return self.request(
           ^^^^^^^^^^^^^
  File "C:\Program Files\Python312\Lib\site-packages\httpx\_client.py", line 600, in request
    return self.send(
           ^^^^^^^^^^
  File "C:\Program Files\Python312\Lib\site-packages\httpx\_client.py", line 620, in send
    response = self.send_handling_redirects(
               ^^^^^^^^^^^^^^^^^^^^^^^^^^^^^
  File "C:\Program Files\Python312\Lib\site-packages\httpx\_client.py", line 647, in send_handling_redirects
    response = self.send_handling_auth(
               ^^^^^^^^^^^^^^^^^^^^^^^^
  File "C:\Program Files\Python312\Lib\site-packages\httpx\_client.py", line 684, in send_handling_auth
    response = self.send_single_request(request, timeout)
               ^^^^^^^^^^^^^^^^^^^^^^^^^^^^^^^^^^^^^^^^^^
  File "C:\Program Files\Python312\Lib\site-packages\httpx\_client.py", line 714, in send_single_request
    ) = transport.request(
        ^^^^^^^^^^^^^^^^^^
  File "C:\Program Files\Python312\Lib\site-packages\httpcore\_sync\connection_pool.py", line 152, in request
    response = connection.request(
               ^^^^^^^^^^^^^^^^^^^
  File "C:\Program Files\Python312\Lib\site-packages\httpcore\_sync\connection.py", line 65, in request
    self.socket = self._open_socket(timeout)
                  ^^^^^^^^^^^^^^^^^^^^^^^^^^
  File "C:\Program Files\Python312\Lib\site-packages\httpcore\_sync\connection.py", line 85, in _open_socket
    return self.backend.open_tcp_stream(
           ^^^^^^^^^^^^^^^^^^^^^^^^^^^^^
  File "C:\Program Files\Python312\Lib\site-packages\httpcore\_backends\sync.py", line 133, in open_tcp_stream
    with map_exceptions(exc_map):
  File "C:\Users\cs439\AppData\Local\Programs\Python\Python312\Lib\contextlib.py", line 155, in __exit__
    self.gen.throw(value)
  File "C:\Program Files\Python312\Lib\site-packages\httpcore\_exceptions.py", line 12, in map_exceptions
    raise to_exc(exc) from None
httpcore._exceptions.ConnectError: [Errno 11001] getaddrinfo failed
2023-10-29 16:29:46,913 - INFO - Translated 30 characters, 5 words, and 1 sentences from Turkish to Zulu.
2023-10-29 16:30:05,582 - ERROR - [Errno 11001] getaddrinfo failed
Traceback (most recent call last):
  File "C:\Users\cs439\PycharmProjects\pythonProject4\main.py", line 89, in translate_docx
    translated_chunk = translator.translate(chunk, src=src_lang, dest=dest_lang).text
                       ^^^^^^^^^^^^^^^^^^^^^^^^^^^^^^^^^^^^^^^^^^^^^^^^^^^^^^^^^
  File "C:\Program Files\Python312\Lib\site-packages\googletrans\client.py", line 194, in translate
    data, response = self._translate(text, dest, src)
                     ^^^^^^^^^^^^^^^^^^^^^^^^^^^^^^^^
  File "C:\Program Files\Python312\Lib\site-packages\googletrans\client.py", line 120, in _translate
    r = self.client.post(url, params=params, data=data)
        ^^^^^^^^^^^^^^^^^^^^^^^^^^^^^^^^^^^^^^^^^^^^^^^
  File "C:\Program Files\Python312\Lib\site-packages\httpx\_client.py", line 824, in post
    return self.request(
           ^^^^^^^^^^^^^
  File "C:\Program Files\Python312\Lib\site-packages\httpx\_client.py", line 600, in request
    return self.send(
           ^^^^^^^^^^
  File "C:\Program Files\Python312\Lib\site-packages\httpx\_client.py", line 620, in send
    response = self.send_handling_redirects(
               ^^^^^^^^^^^^^^^^^^^^^^^^^^^^^
  File "C:\Program Files\Python312\Lib\site-packages\httpx\_client.py", line 647, in send_handling_redirects
    response = self.send_handling_auth(
               ^^^^^^^^^^^^^^^^^^^^^^^^
  File "C:\Program Files\Python312\Lib\site-packages\httpx\_client.py", line 684, in send_handling_auth
    response = self.send_single_request(request, timeout)
               ^^^^^^^^^^^^^^^^^^^^^^^^^^^^^^^^^^^^^^^^^^
  File "C:\Program Files\Python312\Lib\site-packages\httpx\_client.py", line 714, in send_single_request
    ) = transport.request(
        ^^^^^^^^^^^^^^^^^^
  File "C:\Program Files\Python312\Lib\site-packages\httpcore\_sync\connection_pool.py", line 152, in request
    response = connection.request(
               ^^^^^^^^^^^^^^^^^^^
  File "C:\Program Files\Python312\Lib\site-packages\httpcore\_sync\connection.py", line 65, in request
    self.socket = self._open_socket(timeout)
                  ^^^^^^^^^^^^^^^^^^^^^^^^^^
  File "C:\Program Files\Python312\Lib\site-packages\httpcore\_sync\connection.py", line 85, in _open_socket
    return self.backend.open_tcp_stream(
           ^^^^^^^^^^^^^^^^^^^^^^^^^^^^^
  File "C:\Program Files\Python312\Lib\site-packages\httpcore\_backends\sync.py", line 133, in open_tcp_stream
    with map_exceptions(exc_map):
  File "C:\Users\cs439\AppData\Local\Programs\Python\Python312\Lib\contextlib.py", line 155, in __exit__
    self.gen.throw(value)
  File "C:\Program Files\Python312\Lib\site-packages\httpcore\_exceptions.py", line 12, in map_exceptions
    raise to_exc(exc) from None
httpcore._exceptions.ConnectError: [Errno 11001] getaddrinfo failed
2023-10-29 16:30:05,583 - INFO - Translated 30 characters, 5 words, and 1 sentences from Turkish to English.
2023-10-29 16:35:11,269 - ERROR - The read operation timed out
Traceback (most recent call last):
  File "C:\Users\cs439\PycharmProjects\pythonProject4\main.py", line 89, in translate_docx
    translated_chunk = translator.translate(chunk, src=src_lang, dest=dest_lang).text
                       ^^^^^^^^^^^^^^^^^^^^^^^^^^^^^^^^^^^^^^^^^^^^^^^^^^^^^^^^^
  File "C:\Program Files\Python312\Lib\site-packages\googletrans\client.py", line 194, in translate
    data, response = self._translate(text, dest, src)
                     ^^^^^^^^^^^^^^^^^^^^^^^^^^^^^^^^
  File "C:\Program Files\Python312\Lib\site-packages\googletrans\client.py", line 120, in _translate
    r = self.client.post(url, params=params, data=data)
        ^^^^^^^^^^^^^^^^^^^^^^^^^^^^^^^^^^^^^^^^^^^^^^^
  File "C:\Program Files\Python312\Lib\site-packages\httpx\_client.py", line 824, in post
    return self.request(
           ^^^^^^^^^^^^^
  File "C:\Program Files\Python312\Lib\site-packages\httpx\_client.py", line 600, in request
    return self.send(
           ^^^^^^^^^^
  File "C:\Program Files\Python312\Lib\site-packages\httpx\_client.py", line 620, in send
    response = self.send_handling_redirects(
               ^^^^^^^^^^^^^^^^^^^^^^^^^^^^^
  File "C:\Program Files\Python312\Lib\site-packages\httpx\_client.py", line 647, in send_handling_redirects
    response = self.send_handling_auth(
               ^^^^^^^^^^^^^^^^^^^^^^^^
  File "C:\Program Files\Python312\Lib\site-packages\httpx\_client.py", line 684, in send_handling_auth
    response = self.send_single_request(request, timeout)
               ^^^^^^^^^^^^^^^^^^^^^^^^^^^^^^^^^^^^^^^^^^
  File "C:\Program Files\Python312\Lib\site-packages\httpx\_client.py", line 714, in send_single_request
    ) = transport.request(
        ^^^^^^^^^^^^^^^^^^
  File "C:\Program Files\Python312\Lib\site-packages\httpcore\_sync\connection_pool.py", line 152, in request
    response = connection.request(
               ^^^^^^^^^^^^^^^^^^^
  File "C:\Program Files\Python312\Lib\site-packages\httpcore\_sync\connection.py", line 78, in request
    return self.connection.request(method, url, headers, stream, timeout)
           ^^^^^^^^^^^^^^^^^^^^^^^^^^^^^^^^^^^^^^^^^^^^^^^^^^^^^^^^^^^^^^
  File "C:\Program Files\Python312\Lib\site-packages\httpcore\_sync\http2.py", line 118, in request
    return h2_stream.request(method, url, headers, stream, timeout)
           ^^^^^^^^^^^^^^^^^^^^^^^^^^^^^^^^^^^^^^^^^^^^^^^^^^^^^^^^
  File "C:\Program Files\Python312\Lib\site-packages\httpcore\_sync\http2.py", line 292, in request
    status_code, headers = self.receive_response(timeout)
                           ^^^^^^^^^^^^^^^^^^^^^^^^^^^^^^
  File "C:\Program Files\Python312\Lib\site-packages\httpcore\_sync\http2.py", line 344, in receive_response
    event = self.connection.wait_for_event(self.stream_id, timeout)
            ^^^^^^^^^^^^^^^^^^^^^^^^^^^^^^^^^^^^^^^^^^^^^^^^^^^^^^^
  File "C:\Program Files\Python312\Lib\site-packages\httpcore\_sync\http2.py", line 197, in wait_for_event
    self.receive_events(timeout)
  File "C:\Program Files\Python312\Lib\site-packages\httpcore\_sync\http2.py", line 204, in receive_events
    data = self.socket.read(self.READ_NUM_BYTES, timeout)
           ^^^^^^^^^^^^^^^^^^^^^^^^^^^^^^^^^^^^^^^^^^^^^^
  File "C:\Program Files\Python312\Lib\site-packages\httpcore\_backends\sync.py", line 60, in read
    with map_exceptions(exc_map):
  File "C:\Users\cs439\AppData\Local\Programs\Python\Python312\Lib\contextlib.py", line 155, in __exit__
    self.gen.throw(value)
  File "C:\Program Files\Python312\Lib\site-packages\httpcore\_exceptions.py", line 12, in map_exceptions
    raise to_exc(exc) from None
httpcore._exceptions.ReadTimeout: The read operation timed out
2023-10-29 16:35:11,279 - INFO - Translated 22 characters, 4 words, and 1 sentences from Turkish to German.
